<?xml version="1.0"?>
<robot xmlns:xacro="http://www.ros.org/wiki/xacro">
  <xacro:macro name="table" params="prefix parent sd *origin">
    <xacro:include filename="$(find acin_support)/urdf/macros.xacro"/>
    <xacro:property name="path" value="package://acin_support/meshes/table"/>
    <material name="gray">
      <color rgba="0.2 0.2 0.2 1"/>
    </material>

    <!-- Macros for table -->
    <xacro:macro name="profile_1220x160x40" params="xshift">
      <xacro:visual_mesh filename="${path}/profile_1220x160x40.dae">
        <origin xyz="${xshift} 0 -0.020"/>
      </xacro:visual_mesh>
    </xacro:macro>
    <xacro:macro name="profile_952x40x40" params="yshift">
      <xacro:visual_mesh filename="${path}/profile_952x40x40.dae">
        <origin xyz="0 ${yshift} -0.020" rpy="0 0 ${pi/2}"/>
      </xacro:visual_mesh>
    </xacro:macro>
    <xacro:macro name="cap_4x40x40" params="xshift yshift reflect">
      <xacro:visual_mesh filename="${path}/cap_4x40x40.dae">
        <origin xyz="${xshift} ${yshift} -0.020" rpy="0 ${reflect*pi/2} 0"/>
      </xacro:visual_mesh>
    </xacro:macro>
    <xacro:macro name="leg_bottom" params="yshift">
      <visual>
        <origin xyz="0 ${yshift} 0.010"/>
        <geometry>
          <box size="0.740 0.080 0.020"/>
        </geometry>
        <material name="gray"/>
      </visual>
      <visual>
        <origin xyz="0 ${yshift} 0.320"/>
        <geometry>
          <box size="0.080 0.080 0.600"/>
        </geometry>
        <material name="gray"/>
      </visual>
      <xacro:collision_box size="${0.740+2*sd} ${0.080+2*sd} ${0.020+sd}">
        <origin xyz="0 ${yshift} ${0.010+sd/2}"/>
      </xacro:collision_box>
      <xacro:collision_box size="${0.080+2*sd} ${0.080+2*sd} ${0.600+sd}">
        <origin xyz="0 ${yshift} ${0.320+sd/2}"/>
      </xacro:collision_box>
    </xacro:macro>
    <xacro:macro name="leg_middle" params="yshift">
      <visual>
        <origin xyz="0 ${yshift} -0.320"/>
        <geometry>
          <box size="0.070 0.070 0.600"/>
        </geometry>
        <material name="gray"/>
      </visual>
      <xacro:collision_box size="${0.070+2*sd} ${0.070+2*sd} ${0.600+sd}">
        <origin xyz="0 ${yshift} ${-0.320+sd/2}"/>
      </xacro:collision_box>
    </xacro:macro>
    <xacro:macro name="leg_top" params="yshift">
      <visual>
        <origin xyz="0 ${yshift} -0.360"/>
        <geometry>
          <box size="0.060 0.060 0.600"/>
        </geometry>
        <material name="gray"/>
      </visual>
      <visual>
        <origin xyz="0 ${yshift} -0.050"/>
        <geometry>
          <box size="0.585 0.060 0.020"/>
        </geometry>
        <material name="gray"/>
      </visual>
      <xacro:collision_box size="${0.060+2*sd} ${0.060+2*sd} ${0.600+sd}">
        <origin xyz="0 ${yshift} ${-0.360+sd/2}"/>
      </xacro:collision_box>
      <xacro:collision_box size="${0.585+2*sd} ${0.060+2*sd} ${0.020+2*sd}">
        <origin xyz="0 ${yshift} -0.050"/>
      </xacro:collision_box>
    </xacro:macro>

    <!-- Actual table -->
    <link name="${prefix}link_0">
      <xacro:leg_bottom yshift="-0.450"/>
      <xacro:leg_bottom yshift="+0.450"/>
      <inertial>
        <mass value="1"/>
        <inertia ixx="1" ixy="0" ixz="0" iyy="1" iyz="0" izz="1"/>
      </inertial>
    </link>
    <link name="${prefix}link_1">
      <xacro:leg_middle yshift="-0.450"/>
      <xacro:leg_middle yshift="+0.450"/>
      <inertial>
        <mass value="1"/>
        <inertia ixx="1" ixy="0" ixz="0" iyy="1" iyz="0" izz="1"/>
      </inertial>
    </link>
    <link name="${prefix}link_2">
      <xacro:leg_top yshift="-0.450"/>
      <xacro:leg_top yshift="+0.450"/>
      <xacro:profile_952x40x40 yshift="-0.630"/>
      <xacro:profile_952x40x40 yshift="+0.630"/>
      <xacro:profile_1220x160x40 xshift="-0.400"/>
      <xacro:profile_1220x160x40 xshift="-0.240"/>
      <xacro:profile_1220x160x40 xshift="-0.080"/>
      <xacro:profile_1220x160x40 xshift="+0.080"/>
      <xacro:profile_1220x160x40 xshift="+0.240"/>
      <xacro:profile_1220x160x40 xshift="+0.400"/>
      <xacro:cap_4x40x40 xshift="-0.476" yshift="-0.630" reflect="-1"/>
      <xacro:cap_4x40x40 xshift="-0.476" yshift="+0.630" reflect="-1"/>
      <xacro:cap_4x40x40 xshift="+0.476" yshift="-0.630" reflect="+1"/>
      <xacro:cap_4x40x40 xshift="+0.476" yshift="+0.630" reflect="+1"/>
      <xacro:collision_box size="${0.960+2*sd} ${1.300+2*sd} ${0.040+2*sd}">
        <origin xyz="0 0 -0.020"/>
      </xacro:collision_box>
      <inertial>
        <mass value="1"/>
        <inertia ixx="1" ixy="0" ixz="0" iyy="1" iyz="0" izz="1"/>
      </inertial>
    </link>

    <joint name="${prefix}joint_0" type="fixed">
      <xacro:insert_block name="origin"/>
      <parent link="${parent}"/>
      <child link="${prefix}link_0"/>
    </joint>
    <joint name="${prefix}joint_1" type="prismatic">
      <axis xyz="0 0 1"/>
      <origin xyz="0 0 0.640"/>
      <limit effort="0" velocity="0.018" lower="0.000" upper="0.325"/>
      <mimic joint="${prefix}joint_2" multiplier="0.5" offset="0"/>
      <parent link="${prefix}link_0"/>
      <child link="${prefix}link_1"/>
    </joint>
    <joint name="${prefix}joint_2" type="prismatic">
      <axis xyz="0 0 1"/>
      <origin xyz="0 0 0.680"/>
      <limit effort="0" velocity="0.036" lower="0.000" upper="0.650"/>
      <parent link="${prefix}link_0"/>
      <child link="${prefix}link_2"/>
    </joint>

    <gazebo reference="${prefix}link_0">
      <material>Gazebo/Black</material>
    </gazebo>
    <gazebo reference="${prefix}link_1">
      <material>Gazebo/Black</material>
    </gazebo>
    <xacro:gazebo_material reference="${prefix}link_2"/>
  </xacro:macro>
</robot>
